<mujoco model="humanoid">
  <compiler coordinate="local"/>
  <statistic extent="2" center="0 0 1"/>
  <option timestep="0.00555"/>
  <default>
    <motor ctrlrange="-1 1" ctrllimited="true"/>
    <geom type="capsule" condim="1" friction="1.0 0.05 0.05" solimp=".9 .99 .003" solref=".015 1"/>
    <joint type="hinge" damping="0.1" stiffness="5" armature=".007" limited="true" solimplimit="0 .99 .01"/>
    <site size=".04" group="3"/>
    <default class="force-torque">
      <site type="box" size=".01 .01 .02" rgba="1 0 0 1"/>
    </default>
    <default class="touch">
      <site type="capsule" rgba="0 0 1 .3"/>
    </default>
  </default>
  <asset>
    <texture type="skybox" builtin="gradient" rgb1=".4 .5 .6" rgb2="0 0 0" width="100" height="100"/>
    <texture builtin="flat" height="1278" mark="cross" markrgb="1 1 1" name="texgeom" random="0.01" rgb1="0.8 0.6 0.4" rgb2="0.8 0.6 0.4" type="cube" width="127"/>
    <texture builtin="checker" height="100" name="texplane" rgb1="0 0 0" rgb2="0.8 0.8 0.8" type="2d" width="100"/>
    <material name="MatPlane" reflectance="0.5" shininess="1" specular="1" texrepeat="60 60" texture="texplane"/>
    <material name="geom" texture="texgeom" texuniform="true"/>
  </asset>
  <worldbody>
    <light cutoff="100" diffuse="1 1 1" dir="-0 0 -1.3" directional="true" exponent="1" pos="0 0 1.3" specular=".1 .1 .1"/>
    <geom conaffinity="1" condim="3" name="floor" pos="0 0 0" rgba="0.8 0.9 0.8 1" size="100 100 .2" type="plane" material="MatPlane"/>
    <body name="R_Wrist" pos="-0.2493 -0.0045 -0.0153">
                    <joint name="R_Wrist_x" type="hinge" pos="0 0 0" axis="1 0 0" stiffness="100" damping="10" armature="0.02" range="-180.0000 180.0000"/>
                    <joint name="R_Wrist_y" type="hinge" pos="0 0 0" axis="0 1 0" stiffness="100" damping="10" armature="0.02" range="-180.0000 180.0000"/>
                    <joint name="R_Wrist_z" type="hinge" pos="0 0 0" axis="0 0 1" stiffness="100" damping="10" armature="0.02" range="-180.0000 180.0000"/>
                    <geom type="capsule" contype="1" conaffinity="1" density="1000" fromto="-0.0169 -0.0029 -0.0012 -0.0677 -0.0116 -0.0046" size="0.01"/>
                    <body name="R_Index1" pos="-0.0999 -0.0118 0.0196">
                      <joint name="R_Index1_x" type="hinge" pos="0 0 0" axis="1 0 0" stiffness="100" damping="10" armature="0.02" range="-180.0000 180.0000"/>
                      <joint name="R_Index1_y" type="hinge" pos="0 0 0" axis="0 1 0" stiffness="100" damping="10" armature="0.02" range="-180.0000 180.0000"/>
                      <joint name="R_Index1_z" type="hinge" pos="0 0 0" axis="0 0 1" stiffness="100" damping="10" armature="0.02" range="-180.0000 180.0000"/>
                      <geom type="capsule" contype="1" conaffinity="1" density="1000" fromto="-0.0060 -0.0022 0.0002 -0.0241 -0.0089 0.0009" size="0.0092"/>
                      <body name="R_Index2" pos="-0.0301 -0.0112 0.0012">
                        <joint name="R_Index2_x" type="hinge" pos="0 0 0" axis="1 0 0" stiffness="100" damping="10" armature="0.02" range="-180.0000 180.0000"/>
                        <joint name="R_Index2_y" type="hinge" pos="0 0 0" axis="0 1 0" stiffness="100" damping="10" armature="0.02" range="-180.0000 180.0000"/>
                        <joint name="R_Index2_z" type="hinge" pos="0 0 0" axis="0 0 1" stiffness="100" damping="10" armature="0.02" range="-180.0000 180.0000"/>
                        <geom type="capsule" contype="1" conaffinity="1" density="1000" fromto="-0.0013 -0.0043 -0.0005 -0.0052 -0.0173 -0.0019" size="0.0076"/>
                        <body name="R_Index3" pos="-0.0065 -0.0216 -0.0024">
                          <joint name="R_Index3_x" type="hinge" pos="0 0 0" axis="1 0 0" stiffness="100" damping="10" armature="0.02" range="-180.0000 180.0000"/>
                          <joint name="R_Index3_y" type="hinge" pos="0 0 0" axis="0 1 0" stiffness="100" damping="10" armature="0.02" range="-180.0000 180.0000"/>
                          <joint name="R_Index3_z" type="hinge" pos="0 0 0" axis="0 0 1" stiffness="100" damping="10" armature="0.02" range="-180.0000 180.0000"/>
                          <geom type="capsule" contype="1" conaffinity="1" density="1000" fromto="-0.0009 -0.0039 -0.0001 -0.0036 -0.0157 -0.0003" size="0.0069"/>
                        </body>
                      </body>
                    </body>
                    <body name="R_Middle1" pos="-0.1074 -0.0094 -0.0037">
                      <joint name="R_Middle1_x" type="hinge" pos="0 0 0" axis="1 0 0" stiffness="100" damping="10" armature="0.02" range="-180.0000 180.0000"/>
                      <joint name="R_Middle1_y" type="hinge" pos="0 0 0" axis="0 1 0" stiffness="100" damping="10" armature="0.02" range="-180.0000 180.0000"/>
                      <joint name="R_Middle1_z" type="hinge" pos="0 0 0" axis="0 0 1" stiffness="100" damping="10" armature="0.02" range="-180.0000 180.0000"/>
                      <geom type="capsule" contype="1" conaffinity="1" density="1000" fromto="-0.0053 -0.0030 -0.0009 -0.0212 -0.0122 -0.0037" size="0.0094"/>
                      <body name="R_Middle2" pos="-0.0265 -0.0152 -0.0046">
                        <joint name="R_Middle2_x" type="hinge" pos="0 0 0" axis="1 0 0" stiffness="100" damping="10" armature="0.02" range="-180.0000 180.0000"/>
                        <joint name="R_Middle2_y" type="hinge" pos="0 0 0" axis="0 1 0" stiffness="100" damping="10" armature="0.02" range="-180.0000 180.0000"/>
                        <joint name="R_Middle2_z" type="hinge" pos="0 0 0" axis="0 0 1" stiffness="100" damping="10" armature="0.02" range="-180.0000 180.0000"/>
                        <geom type="capsule" contype="1" conaffinity="1" density="1000" fromto="-0.0010 -0.0047 -0.0004 -0.0040 -0.0187 -0.0015" size="0.0071"/>
                        <body name="R_Middle3" pos="-0.005 -0.0233 -0.0019">
                          <joint name="R_Middle3_x" type="hinge" pos="0 0 0" axis="1 0 0" stiffness="100" damping="10" armature="0.02" range="-180.0000 180.0000"/>
                          <joint name="R_Middle3_y" type="hinge" pos="0 0 0" axis="0 1 0" stiffness="100" damping="10" armature="0.02" range="-180.0000 180.0000"/>
                          <joint name="R_Middle3_z" type="hinge" pos="0 0 0" axis="0 0 1" stiffness="100" damping="10" armature="0.02" range="-180.0000 180.0000"/>
                          <geom type="capsule" contype="1" conaffinity="1" density="1000" fromto="-0.0006 -0.0043 0.0000 -0.0024 -0.0171 0.0001" size="0.0064"/>
                        </body>
                      </body>
                    </body>
                    <body name="R_Pinky1" pos="-0.082 -0.0176 -0.0435">
                      <joint name="R_Pinky1_x" type="hinge" pos="0 0 0" axis="1 0 0" stiffness="100" damping="10" armature="0.02" range="-180.0000 180.0000"/>
                      <joint name="R_Pinky1_y" type="hinge" pos="0 0 0" axis="0 1 0" stiffness="100" damping="10" armature="0.02" range="-180.0000 180.0000"/>
                      <joint name="R_Pinky1_z" type="hinge" pos="0 0 0" axis="0 0 1" stiffness="100" damping="10" armature="0.02" range="-180.0000 180.0000"/>
                      <geom type="capsule" contype="1" conaffinity="1" density="1000" fromto="-0.0024 -0.0029 -0.0011 -0.0097 -0.0116 -0.0043" size="0.007"/>
                      <body name="R_Pinky2" pos="-0.0121 -0.0144 -0.0054">
                        <joint name="R_Pinky2_x" type="hinge" pos="0 0 0" axis="1 0 0" stiffness="100" damping="10" armature="0.02" range="-180.0000 180.0000"/>
                        <joint name="R_Pinky2_y" type="hinge" pos="0 0 0" axis="0 1 0" stiffness="100" damping="10" armature="0.02" range="-180.0000 180.0000"/>
                        <joint name="R_Pinky2_z" type="hinge" pos="0 0 0" axis="0 0 1" stiffness="100" damping="10" armature="0.02" range="-180.0000 180.0000"/>
                        <geom type="capsule" contype="1" conaffinity="1" density="1000" fromto="-0.0008 -0.0038 0.0000 -0.0030 -0.0151 0.0001" size="0.0063"/>
                        <body name="R_Pinky3" pos="-0.0038 -0.0189 0.0002">
                          <joint name="R_Pinky3_x" type="hinge" pos="0 0 0" axis="1 0 0" stiffness="100" damping="10" armature="0.02" range="-180.0000 180.0000"/>
                          <joint name="R_Pinky3_y" type="hinge" pos="0 0 0" axis="0 1 0" stiffness="100" damping="10" armature="0.02" range="-180.0000 180.0000"/>
                          <joint name="R_Pinky3_z" type="hinge" pos="0 0 0" axis="0 0 1" stiffness="100" damping="10" armature="0.02" range="-180.0000 180.0000"/>
                          <geom type="capsule" contype="1" conaffinity="1" density="1000" fromto="-0.0004 -0.0034 0.0004 -0.0014 -0.0135 0.0017" size="0.0052"/>
                        </body>
                      </body>
                    </body>
                    <body name="R_Ring1" pos="-0.0954 -0.0124 -0.0271">
                      <joint name="R_Ring1_x" type="hinge" pos="0 0 0" axis="1 0 0" stiffness="100" damping="10" armature="0.02" range="-180.0000 180.0000"/>
                      <joint name="R_Ring1_y" type="hinge" pos="0 0 0" axis="0 1 0" stiffness="100" damping="10" armature="0.02" range="-180.0000 180.0000"/>
                      <joint name="R_Ring1_z" type="hinge" pos="0 0 0" axis="0 0 1" stiffness="100" damping="10" armature="0.02" range="-180.0000 180.0000"/>
                      <geom type="capsule" contype="1" conaffinity="1" density="1000" fromto="-0.0047 -0.0032 -0.0004 -0.0188 -0.0128 -0.0015" size="0.0079"/>
                      <body name="R_Ring2" pos="-0.0236 -0.0161 -0.0019">
                        <joint name="R_Ring2_x" type="hinge" pos="0 0 0" axis="1 0 0" stiffness="100" damping="10" armature="0.02" range="-180.0000 180.0000"/>
                        <joint name="R_Ring2_y" type="hinge" pos="0 0 0" axis="0 1 0" stiffness="100" damping="10" armature="0.02" range="-180.0000 180.0000"/>
                        <joint name="R_Ring2_z" type="hinge" pos="0 0 0" axis="0 0 1" stiffness="100" damping="10" armature="0.02" range="-180.0000 180.0000"/>
                        <geom type="capsule" contype="1" conaffinity="1" density="1000" fromto="-0.0009 -0.0047 0.0002 -0.0034 -0.0188 0.0007" size="0.0072"/>
                        <body name="R_Ring3" pos="-0.0043 -0.0235 0.0008">
                          <joint name="R_Ring3_x" type="hinge" pos="0 0 0" axis="1 0 0" stiffness="100" damping="10" armature="0.02" range="-180.0000 180.0000"/>
                          <joint name="R_Ring3_y" type="hinge" pos="0 0 0" axis="0 1 0" stiffness="100" damping="10" armature="0.02" range="-180.0000 180.0000"/>
                          <joint name="R_Ring3_z" type="hinge" pos="0 0 0" axis="0 0 1" stiffness="100" damping="10" armature="0.02" range="-180.0000 180.0000"/>
                          <geom type="capsule" contype="1" conaffinity="1" density="1000" fromto="-0.0005 -0.0043 0.0006 -0.0018 -0.0172 0.0023" size="0.006"/>
                        </body>
                      </body>
                    </body>
                    <body name="R_Thumb1" pos="-0.0386 -0.0211 0.0259">
                      <joint name="R_Thumb1_x" type="hinge" pos="0 0 0" axis="1 0 0" stiffness="100" damping="10" armature="0.02" range="-180.0000 180.0000"/>
                      <joint name="R_Thumb1_y" type="hinge" pos="0 0 0" axis="0 1 0" stiffness="100" damping="10" armature="0.02" range="-180.0000 180.0000"/>
                      <joint name="R_Thumb1_z" type="hinge" pos="0 0 0" axis="0 0 1" stiffness="100" damping="10" armature="0.02" range="-180.0000 180.0000"/>
                      <geom type="capsule" contype="1" conaffinity="1" density="1000" fromto="-0.0043 -0.0035 0.0023 -0.0173 -0.0141 0.0093" size="0.0122"/>
                      <body name="R_Thumb2" pos="-0.0216 -0.0176 0.0116">
                        <joint name="R_Thumb2_x" type="hinge" pos="0 0 0" axis="1 0 0" stiffness="100" damping="10" armature="0.02" range="-180.0000 180.0000"/>
                        <joint name="R_Thumb2_y" type="hinge" pos="0 0 0" axis="0 1 0" stiffness="100" damping="10" armature="0.02" range="-180.0000 180.0000"/>
                        <joint name="R_Thumb2_z" type="hinge" pos="0 0 0" axis="0 0 1" stiffness="100" damping="10" armature="0.02" range="-180.0000 180.0000"/>
                        <geom type="capsule" contype="1" conaffinity="1" density="1000" fromto="-0.0048 -0.0017 0.0013 -0.0192 -0.0067 0.0052" size="0.0093"/>
                        <body name="R_Thumb3" pos="-0.024 -0.0084 0.0065">
                          <joint name="R_Thumb3_x" type="hinge" pos="0 0 0" axis="1 0 0" stiffness="100" damping="10" armature="0.02" range="-180.0000 180.0000"/>
                          <joint name="R_Thumb3_y" type="hinge" pos="0 0 0" axis="0 1 0" stiffness="100" damping="10" armature="0.02" range="-180.0000 180.0000"/>
                          <joint name="R_Thumb3_z" type="hinge" pos="0 0 0" axis="0 0 1" stiffness="100" damping="10" armature="0.02" range="-180.0000 180.0000"/>
                          <geom type="capsule" contype="1" conaffinity="1" density="1000" fromto="-0.0044 -0.0013 0.0017 -0.0176 -0.0051 0.0068" size="0.009"/>
                        </body>
                      </body>
                    </body>

    </body>
  </worldbody>
  <actuator>
    <motor name="R_Wrist_x" joint="R_Wrist_x" gear="500"/>
    <motor name="R_Wrist_y" joint="R_Wrist_y" gear="500"/>
    <motor name="R_Wrist_z" joint="R_Wrist_z" gear="500"/>
    <motor name="R_Index1_x" joint="R_Index1_x" gear="500"/>
    <motor name="R_Index1_y" joint="R_Index1_y" gear="500"/>
    <motor name="R_Index1_z" joint="R_Index1_z" gear="500"/>
    <motor name="R_Index2_x" joint="R_Index2_x" gear="500"/>
    <motor name="R_Index2_y" joint="R_Index2_y" gear="500"/>
    <motor name="R_Index2_z" joint="R_Index2_z" gear="500"/>
    <motor name="R_Index3_x" joint="R_Index3_x" gear="500"/>
    <motor name="R_Index3_y" joint="R_Index3_y" gear="500"/>
    <motor name="R_Index3_z" joint="R_Index3_z" gear="500"/>
    <motor name="R_Middle1_x" joint="R_Middle1_x" gear="500"/>
    <motor name="R_Middle1_y" joint="R_Middle1_y" gear="500"/>
    <motor name="R_Middle1_z" joint="R_Middle1_z" gear="500"/>
    <motor name="R_Middle2_x" joint="R_Middle2_x" gear="500"/>
    <motor name="R_Middle2_y" joint="R_Middle2_y" gear="500"/>
    <motor name="R_Middle2_z" joint="R_Middle2_z" gear="500"/>
    <motor name="R_Middle3_x" joint="R_Middle3_x" gear="500"/>
    <motor name="R_Middle3_y" joint="R_Middle3_y" gear="500"/>
    <motor name="R_Middle3_z" joint="R_Middle3_z" gear="500"/>
    <motor name="R_Pinky1_x" joint="R_Pinky1_x" gear="500"/>
    <motor name="R_Pinky1_y" joint="R_Pinky1_y" gear="500"/>
    <motor name="R_Pinky1_z" joint="R_Pinky1_z" gear="500"/>
    <motor name="R_Pinky2_x" joint="R_Pinky2_x" gear="500"/>
    <motor name="R_Pinky2_y" joint="R_Pinky2_y" gear="500"/>
    <motor name="R_Pinky2_z" joint="R_Pinky2_z" gear="500"/>
    <motor name="R_Pinky3_x" joint="R_Pinky3_x" gear="500"/>
    <motor name="R_Pinky3_y" joint="R_Pinky3_y" gear="500"/>
    <motor name="R_Pinky3_z" joint="R_Pinky3_z" gear="500"/>
    <motor name="R_Ring1_x" joint="R_Ring1_x" gear="500"/>
    <motor name="R_Ring1_y" joint="R_Ring1_y" gear="500"/>
    <motor name="R_Ring1_z" joint="R_Ring1_z" gear="500"/>
    <motor name="R_Ring2_x" joint="R_Ring2_x" gear="500"/>
    <motor name="R_Ring2_y" joint="R_Ring2_y" gear="500"/>
    <motor name="R_Ring2_z" joint="R_Ring2_z" gear="500"/>
    <motor name="R_Ring3_x" joint="R_Ring3_x" gear="500"/>
    <motor name="R_Ring3_y" joint="R_Ring3_y" gear="500"/>
    <motor name="R_Ring3_z" joint="R_Ring3_z" gear="500"/>
    <motor name="R_Thumb1_x" joint="R_Thumb1_x" gear="500"/>
    <motor name="R_Thumb1_y" joint="R_Thumb1_y" gear="500"/>
    <motor name="R_Thumb1_z" joint="R_Thumb1_z" gear="500"/>
    <motor name="R_Thumb2_x" joint="R_Thumb2_x" gear="500"/>
    <motor name="R_Thumb2_y" joint="R_Thumb2_y" gear="500"/>
    <motor name="R_Thumb2_z" joint="R_Thumb2_z" gear="500"/>
    <motor name="R_Thumb3_x" joint="R_Thumb3_x" gear="500"/>
    <motor name="R_Thumb3_y" joint="R_Thumb3_y" gear="500"/>
    <motor name="R_Thumb3_z" joint="R_Thumb3_z" gear="500"/>
  </actuator>
  <contact/>
  <size njmax="700" nconmax="700"/>
</mujoco>